Workbook
Name AdhesiveList: #REF!
Name amount: #REF!
Name BagNamesDropdown: [6]HELPER!$DI$2:$DI$6
Name BagNamesDropdown: HELPER!$DI$2:$DI$6
Name BagTypeList: #REF!
Name Barier: #REF!
Name Clear: #REF!
Name ColorBandsDropdown: [6]HELPER!$DL$2:$DL$5
Name ColorBandsDropdown: HELPER!$DL$2:$DL$5
Name Config_302FG: #REF!
Name Config_302FGW: #REF!
Name Config_306: #REF!
Name Config_308: #REF!
Name Config_312FG: #REF!
Name Config_312W: #REF!
Name Config_NKR: #REF!
Name Config_PL2021: "'Film Pricing- New'!$AF$10:$AF$20"
Name Config_PL2022: "'Film Pricing- New'!$AG$10:$AG$20"
Name Config_PL2023: "'Film Pricing- New'!$AH$10:$AH$20"
Name ConverterDropdown: [6]HELPER!$DM$2:$DM$4
Name ConverterDropdown: HELPER!$DM$2:$DM$4
Name Family: #REF!
Name Film_type: '[1]List of names'!$Y$15:$Y$16
Name Film_type: #REF!
Name FilmList: #REF!
Name FilmNamesDropdown: [6]HELPER!$DJ$5:$DJ$11
Name FilmNamesDropdown: HELPER!$DJ$5:$DJ$11
Name GF048.1: #REF!
Name Grouped: #REF!
Name HardenerList: #REF!
Name JOB: OFFSET('[2]GEF063 WP Sales'!B6,0,0,COUNTA('[2]GEF063 WP Sales'!$AS$11:$AS$200),COUNTA('[2]GEF063 WP Sales'!$AS$11:$AT$11))
Name JOB: OFFSET(#REF!,0,0,COUNTA(#REF!),COUNTA(#REF!))
Name Jobs: '[2]GEF063 WP Sales'!$AS$10:$AS$210+'[2]GEF063 WP Sales'!$AU$10-2
Name Jobs: #REF!+#REF!-2
Name Jobss: '[2]GEF063 WP Sales'!XFC2:XFC2+VALUE('[2]GEF063 WP Sales'!$AU$10)
Name Jobss: #REF!+VALUE(#REF!)
Name Laminate: '[1]List of names'!$P$15:$P$22
Name Laminate: #REF!
Name Laminate_Thickness: #REF!
Name Laminate_type: '[1]List of names'!$P$14:$X$14
Name Laminate_type: #REF!
Name Laminate106: #REF!
Name Laminate604: [1]!Table4[Laminate618]
Name Laminate604: #REF!
Name Laminate607: #REF!
Name Laminate607\: [1]!Table6[Laminate607]
Name Laminate607\: #REF!
Name Laminate608W: [1]!Table3[Laminate608W]
Name Laminate608W: #REF!
Name LaminateList: #REF!
Name MATERIAL: '[3]Raw materials prices'!$L$51:$L$61
Name MATERIAL: #REF!
Name Materials: '[4]list for drop down menu'!$A$1:$A$20
Name Materials: #REF!
Name Metalize: #REF!
Name NKR: #REF!
Name Paper: #REF!
Name pirce: #REF!
Name PO: #REF!
Name price: #REF!

Sheet Sheet1
A3: Film | B3: Grade | C3: Sum of Price Calculated(€) Thickness & QTY related
A4: TIPA 302FG | B4: S723 | C4: 0.2424
B5: S724 | C5: 0.02352
A6: TIPA 302FG W | B6: S723 | C6: 0.2424
B7: S724 | C7: 0.09408
A8: TIPA 306M | B8: S723 | C8: 0.2424
B9: S724 | C9: 0.0588
A10: TIPA 306W | B10: S723 | C10: 0.2424
B11: S724 | C11: 0.1176
A12: TIPA 312 MFG | B12: S723 | C12: 0.2424
B13: S724 | C13: 0.06762
A14: TIPA 312MFGW | B14: S723 | C14: 0.2424
B15: S724 | C15: 0.06762
A16: Grand Total | C16: 1.88364
A20: Film | B20: Price (€/kg) | C20: Price ($/kg)
A21: PL202.1 | B21: 8.995784 | C21: 10.435109
A22: PL202.2 | B22: 6.73178 | C22: 7.8088648
A23: PL202.3 | B23: 5.74578 | C23: 6.6651048
A24: TIPA 302FG | B24: 3.599712 | C24: 4.1756659
A25: TIPA 302FG W | B25: 3.916872 | C25: 4.5435715
A26: TIPA 306M | B26: 3.520798 | C26: 4.0841257
A27: TIPA 306W | B27: 3.805774 | C27: 4.4146978
A28: TIPA 312 MFG | B28: 2.899978 | C28: 3.3639745
A29: TIPA 312MFGW | B29: 3.178978 | C29: 3.6876145
A32: FILM | B32: Material | C32: % from Total
A33: TIPA 302FG | B33: S723 | C33: =C4/$B$24 -> 0.06733872
B34: S724 | C34: =C5/$B$24 -> 0.006533856
A35: TIPA 302FG W | B35: S723 | C35: =C6/$B$25 -> 0.061886117
B36: S724 | C36: =C7/$B$25 -> 0.024019166
A37: TIPA 306M | B37: S723 | C37: =C8/$B$26 -> 0.068848028
B38: S724 | C38: =C9/$B$26 -> 0.016700759
A39: TIPA 306W | B39: S723 | C39: =C10/$B$27 -> 0.063692694
B40: S724 | C40: =C11/$B$27 -> 0.030900416
A41: TIPA 312 MFG | B41: S723 | C41: =C12/$B$28 -> 0.083586841
B42: S724 | C42: =C13/$B$28 -> 0.023317418
A43: TIPA 312MFGW | B43: S723 | C43: =C14/$B$29 -> 0.076250921
B44: S724 | C44: =C15/$B$29 -> 0.021270987

Sheet Laminate for reels  - Sales
B1: Laminate608 W | C1: Tipa302WFG | E1: Quote in | G1: =C38 -> Ml | H1: =C39 -> 50000
A2: Laminate | B2: Layer | C2: Laminate structure | D2: Width of reel asked | E2: Width Used | F2: length of impression | G2: FG/NF | H2: Laminate length (m) width asked | I2: PR/ NonPR | J2: No of paints | K2: Lemination Width (mm) | L2: Thickness (µ) | M2: Density | N2: Weight (kg) | O2: Raw material Cost | P2: TRANSPORTATION | Q2: Cost (€) | R2: Cost ($) | T2: Cost Per KG | W2: מחיר הדפסה למ"א | X2: מ"א מודפס | AB2: SDR Price
A3: =IF(C36="Laminate607",607,IF(C36="Laminate608",608,IF(C36="Laminate418",418,IF(C36="Laminate608W","608W",IF(C36="Laminate106",106,IF(C36="Laminate428",428,IF(C36="Laminate819",819,IF(C36="Laminate823",823,IF(C36="Laminate618",618,"Check"))))))))) -> 819 | B3: =IF(C3<>"","A","") -> A | C3: =IF(C36="Laminate608W","Tipa302WFG",IF(C36="Laminate418","Tipa312Met",IF(C36="Laminate428","Tipa312Met",IF(C36="Laminate823","Tipa312Met","Tipa302FG")))) -> Tipa302FG | D3: =IF(G1="Impression",B14,B18) -> 260 | E3: =IF(OR(A3<>"608W",A3<>608),IF((K4-29)/D3>6,D3*6,IF((K4-29)/D3>5,D3*5,IF((K4-29)/D3>4,D3*4,IF((K4-29)/D3>3,D3*3,IF((K4-29)/D3>2,D3*2,D3))))),MAX(750,IF((K4-29)/D3>6,D3*6,IF((K4-29)/D3>5,D3*5,IF((K4-29)/D3>4,D3*4,IF((K4-29)/D3>3,D3*3,IF((K4-29)/D3>2,D3*2,D3))))))) -> 1040 | F3: =IF(G1="Impression",B15,"") | G3: =C37 -> FG | H3: =IF(G1="Ml",H1,IF(G1="KG",(1/N8*ROUNDDOWN((K8-30)/D3,0))*H1,H1*F3/1000)) -> 50000 | I3: =C43 -> PR | J3: =C44 -> 5 to 8 | K3: =IF(OR(A3="608W",A3=608),E3+40*2,E3+50) -> 1090 | L3: =IF($AA$4=1,L8-SUM(L4:L5,3),L8-SUM(L4:L5,6)) -> 25 | M3: =VLOOKUP(C3,'[1]List of names'!L:N,3,0) -> 1.25 | N3: =IF(C3="PAPER",42/1000*$K3/1000,M3*1000*(L3/1000000)*($K3/1000)) -> 0.0340625 | O3: =IF(E3<950,'[1]Film -Summary'!Q35,'[1]Film -Summary'!Q35*1.25) -> 10.950906 | P3: =VLOOKUP(C3,'[1]List of names'!$L$2:$M$10,2,FALSE)+Q32 -> 0.2 | Q3: =N3*(O3+P3) -> 0.37982774 | R3: =Q3*USD -> 0.41781051 | T3: =(O3+P3)*N3/$N$8 -> 3.128902 | W3: =Y3/X3 -> 0.1444032 | X3: =IF(OR(A3="608W",A3=608),1/N8,1/N4) -> 27.700217 | Y3: =IF(OR(A3="608W",A3=608),Y11*Y10,IF(J3="1 to 4",Y7,Y8)) -> 4 | Z3: הדפסה לק"ג | AA3: כמות שכבות | AB3: מחיר לק"ג
B4: =IF(C4<>"","B","") -> B | C4: =VLOOKUP(A3,'[1]List of names'!$F$2:$G$11,2,0) -> NKR | K4: =IF(D3<300,D3*4+50,IF(D3<400,D3*3+50,IF(D3<600,D3*2+50,D3+50))) -> 1090 | L4: {=IF(C4="NKR",23,IF(C4="NKME",20,IF(C4="Tipa312Met",25,NA)))} -> 23 | M4: =VLOOKUP(C4,'[1]List of names'!L:N,3,0) -> 1.44 | N4: =IF(C4="PAPER",42/1000*$K4/1000,M4*1000*(L4/1000000)*($K4/1000)) -> 0.0361008 | O4: =VLOOKUP(C4,'[1]Raw material summary'!$I$10:$K$16,IF($K$3<900,2,3),0) -> 7.95 | P4: =VLOOKUP(C4,'[1]List of names'!$L$2:$M$7,2,FALSE)+Q32 -> 0.35 | Q4: =N4*(O4+P4) -> 0.29963664 | R4: =Q4*USD -> 0.3296003 | T4: =(O4+P4)*N4/$N$8 -> 2.4683128 | W4: =Y4/X4 -> 0.29134392 | X4: =1/N8 -> 8.2376869 | Y4: =IF(OR(A3=608,A3="608W"),AA4*Y12*Y10,Y12*AA4*Y10) -> 2.4 | Z4: למינציה לק"ג | AA4: =IF(OR(A3="608W",A3=608,A3=618,A3=418),1,2) -> 2 | AB4: 2.5
B5: =IF(C5<>"","C","") -> C | C5: =IF(VLOOKUP(A3,'[1]List of names'!F2:H11,3,FALSE)=0,"",VLOOKUP(A3,'[1]List of names'!F2:H11,3,FALSE)) -> Paper | K5: =IF(D3<300,D3*4+50,IF(D3<400,D3*3+50,IF(D3<600,D3*2+50,D3+50))) -> 1090 | L5: =IF(C5="","",IF(C5="NKR",23,IF(C5="NKME",20,IF(C5="Paper",67,IF(C5="PBAT",INDEX('[1]List of names'!$F$34:$F$40,MATCH($L$8,'[1]List of names'!$D$34:$D$40,0)),IF(C5="",0,"NA")))))) -> 67 | M5: =IF(C5="",0,VLOOKUP(C5,'[1]List of names'!L2:N7,3,0)) -> 1 | N5: =IF(C5="","",IF(C5="PAPER",42/1000*$K5/1000,M5*1000*(L5/1000000)*($K5/1000))) -> 0.04578 | O5: 1.31 | P5: =IF(C5="",0,VLOOKUP(C5,'[1]List of names'!$L$2:$M$7,2,FALSE)) -> 0.3 | Q5: =IF(C5="","",N5*(O5+P5)) -> 0.0737058 | R5: =IF(C5="","",Q5*USD) -> 0.08107638 | T5: =IF(C5="","",(O5+P5)*N5/$N$8) -> 0.6071653 | W5: =Y5/X5 -> 0.091044975 | X5: =1/N8 -> 8.2376869 | Y5: 0.75 | Z5: חיתוך לק"ג
C6: ADHISIVE | N6: =IF(A3=608,0,(K3/1000*0.0025*IF(B5="C",2,1))) -> 0.00545 | O6: 4.65 | P6: =0.2+Q32 -> 0.2 | Q6: =N6*(O6+P6) -> 0.0264325 | R6: =Q6*USD -> 0.02907575 | T6: =(O6+P6)*N6/$N$8 -> 0.21774266
C7: HARDENER | Q7: =N7*(O7+P7) -> 0 | R7: =Q7*USD -> 0 | T7: =(O7+P7)*N7/$N$8 -> 0 | Y7: 3.5 | Z7: מחיר הדפסה 1-4
A8: =A3 -> 819 | C8: =COUNTA(C3:C5) -> 3 | E8: =COUNTIF(C3:C5,"") -> 0 | G8: Lemingth length width used | H8: =H3/(ROUNDDOWN(K3/D3,0)) -> 12500 | K8: =SUMPRODUCT(K3:K5,L3:L5)/IF(AA4=1,($L$8-3),($L$8-6)) -> 1090 | L8: =C45 -> 121 | N8: =SUM(N3:N7) -> 0.1213933 | P8: Total materials cost | Q8: =SUM(Q3:Q7) -> 0.77960268 | R8: =Q8*USD -> 0.85756295 | T8: =SUM(T3:T7) -> 6.4221228 | Y8: 4 | Z8: מחיר הדפסה 5-8
E9: =IF(OR((680-D3*1)<120,AND((680-D3*2)<120,(680-D3*2)>0),AND((680-D3*3)<120,(680-D3*3)>0)),680,0) -> 0 | L9: =K3*L3+K4*L4 -> 52320 | P9: Lamination | Q9: {=IF(OR(H8="",K8=""),"",IF(K8>1220,"Error! please choose lamination width not higher than 1220",_xlfn.LET(_xlpm.struct,C3:C7,_xlpm.realLayers,SUMPRODUCT(--(_xlpm.struct<>""),--ISERROR(SEARCH("EPOTAL",_xlpm.struct&"")),--ISERROR(SEARCH("BASONAT",_xlpm.struct&"")),--ISERROR(SEARCH("ADH",_xlpm.struct&"")),--ISERROR(SEARCH("HARDENER",_xlpm.struct&""))),_xlpm.lamSteps,MAX(0,_xlpm.realLayers-1),_xlpm.len,H8,_xlpm.colNum,IF(_xlpm.len<3000,1,IF(_xlpm.len<10000,2,IF(_xlpm.len<25000,3,IF(_xlpm.len<50000,4,IF(_xlpm.len<100000,5,IF(_xlpm.len<250000,6,7)))))),_xlpm.widthRow,IF(K8<=990,0,5),_xlpm.baseRate,INDEX('Lmntn & Prntng- Marma & Bastin '!$D$1:$J$22,3+_xlpm.widthRow,_xlpm.colNum),IF(_xlpm.realLayers=0,"",_xlpm.baseRate*_xlpm.lamSteps))))} -> 0.18306 | R9: =Q9*USD -> 0.201366 | T9: =+Y4 -> 2.4
B10: 4 | C10: EURO | E10: =IF(680-D3*1<120,680,0) -> 0 | F10: =IF(C5="NKR",19,IF(C5="NKME",20,IF(C5="",0,"NA"))) -> NA | K10: =IF(OR(A3=607,A3=608),'[1]SDR price list'!Y5,'[1]SDR price list'!Y21) -> 782 | P10: Slitting | Q10: {=IF(OR(H8="",K8=""),"",IF(K8>1220,"Error! please choose lamination width not higher than 1220",_xlfn.LET(_xlpm.len,H8,_xlpm.colNum,IF(_xlpm.len<3000,1,IF(_xlpm.len<10000,2,IF(_xlpm.len<25000,3,IF(_xlpm.len<50000,4,IF(_xlpm.len<100000,5,IF(_xlpm.len<250000,6,7)))))),_xlpm.widthRow,IF(K8<=990,0,5),INDEX('Lmntn & Prntng- Marma & Bastin '!$D$1:$J$22,7+_xlpm.widthRow,_xlpm.colNum))))} -> 0.025916667 | R10: =Q10*USD -> 0.028508333 | T10: =Y5 -> 0.75 | Y10: =IF(L19<300,2,IF(L19<750,1.75,IF(L19<1500,1.5,1))) -> 1 | Z10: מקדם מתחת ל300 ק"ג
B11: 3.6 | C11: $ | P11: Printing | Q11: 0.169 | R11: =Q11*USD -> 0.1859 | T11: =IF(I3="PR",Y3*N4/N8,0) -> 1.1895484 | Y11: 2.5 | Z11: מחיר הדפסה DP | AA11: DP Price
D12: =IF(C36=OR("Laminate418","Laminate428","Laminate823"),"Tipa312Met") -> #VALUE! | N12: =100*N8 -> 12.13933 | P12: Total | Q12: =SUM(Q8:Q11) -> 1.1575793 | R12: =SUM(R8:R11) -> 1.2733373 | T12: =SUM(T8:T11) -> 10.761671 | Y12: 1.2 | Z12: למינציה DP
A13: Impression details | H13: Gross profit | I13: COST | K13: Cost per ml | L13: =$Q13/ROUNDDOWN((K8-30)/D3,0) -> 0.30660086 | M13: =L13*$B$10/$B$11 -> 0.34066762 | P13: Total + 10% | Q13: =Q8*(1+Q17)+SUM(Q9:Q11) -> 1.2264034 | R13: =R12*(1.1) -> 1.400671 | T13: =T8*(1+Q17)+SUM(T9:T11) -> 11.328623
A14: Width | B14: =C40 -> 260 | C14: This is the height of the bag | H14: 0.15 | K14: Cost per kg | L14: =$L13*$L22*K8/E3 -> 10.588436 | M14: =L14*$B$10/$B$11 -> 11.764929 | T14: =T13*(K8/E3) -> 11.873268
A15: Length | B15: 110 | C15: This is the width of the bag | I15: SELL | K15: Price per ml | L15: =$L13/(1-$H14) -> 0.3607069 | M15: =L15*$B$10/$B$11 -> 0.40078544 | X15: Total Weight | Y15: Total Cost
K16: Price per kg | L16: =L14/(1-H14) -> 12.456983 | M16: =L16*$B$10/$B$11 -> 13.841092 | T16: =T8/T12 -> 0.59675888 | X16: =$H$8*N3 -> 425.78125 | Y16: =X16*(O3+P3) -> 4747.8467 | AB16: "680,900,1100"
A17: Reel details | P17: Waste assumption Printed | Q17: =IF(A3=607,(D24*L4/L8+D23+D27*H8)/H8,(D24*L4/L8+D23+D22*0.8+D27*H8)/H8) -> 0.088280992 | X17: =$H$8*N4 -> 451.26 | Y17: =X17*(O4+P4) -> 3745.458
A18: Width | B18: =C40 -> 260 | C18: This is the height of the bag*2 | K18: Printed KG | L18: =L19*L4/L8 -> 288.43449 | P18: Waste assumption Non Printed | Q18: =IF(C5="",(D23+D27*H8)/H8,(D23+D22*0.8+D27*H8)/H8) -> 0.086 | X18: =$H$8*N5 -> 572.25 | Y18: =X18*(O5+P5) -> 921.3225
A19: Length | B19: =C42 -> 0 | C19: to check if there is any length limitation - Must be filled!!! | K19: Total KG | L19: =N8/ROUNDDOWN((K8-29)/D3,0)*H3 -> 1517.4163 | M19: =+L19*N3/N8 -> 425.78125 | X19: =$H$8*N6 -> 68.125 | Y19: =X19*(O6+P6) -> 330.40625
K20: Net KG | L20: =N8/ROUNDDOWN(K8/D3,0)*(E3/K8)*H1 -> 1447.81 | X20: =$H$8*N7 -> 0 | Y20: =X20*O7 -> 0
A21: Waste assumptions | C21: Number of works | D21: Waste per work | K21: Ml & Lem used width of reel in kg | L21: =1/N8 -> 8.2376869 | X21: =SUM(X16:X20) -> 1517.4163 | Y21: =SUM(Y16:Y20) -> 9745.0335
A22: 1st laminate | B22: 1000 | C22: 4 | D22: =B22/C22 -> 250 | K22: Ml & Lem Asked width of reel in kg | L22: =1/N8*ROUNDDOWN(K8/D3,0) -> 32.950748 | P22: Number of impression | Q22: =ROUNDDOWN(K3/D3,0)*1000/B15 -> 36.363636 | X22: Waste of width | Y22: =+(K3/E3*T13-T13)*L19 -> 826.45365
A23: 2nd laminate | B23: 1000 | C23: 4 | D23: =B23/C23 -> 250 | H23: Printed Waste Assumption | P23: Cost per impressiom | Q23: =Q13/Q22 -> 0.033726095 | X23: SDR | Y23: =X21*SUM(T9:T11) -> 6584.9012
A24: Prining | B24: 1200 | C24: 8 | D24: =B24/C24 -> 150 | I24: Eur | K24: USD | P24: Price Per impression | Q24: =Q23*1.25 -> 0.042157618 | R24: =Q24*1.16 -> 0.048902837 | X24: Waste | Y24: =IF(C43="PR",Y21*Q17,Y21*Q18) -> 860.30122
A25: Reel change | B25: 50 | C25: evrey 3K Meter | I25: Cost | J25: Sale price | K25: Cost | L25: Sale price | X25: Total Cost | Y25: =SUM(Y21:Y24) -> 18016.69
A26: Converting | B26: 500 | C26: Set up | H26: ML | I26: =L13 -> 0.30660086 | J26: =L15 -> 0.3607069 | K26: =I26*$O$29 -> 0.35872301 | L26: =J26*$O$29 -> 0.42202707 | P26: Meter MOQ | Q26: =IF(C36="Laminate608",750/N8*(E3/D3),500/N8*(E3/D3)) -> 16475.374 | X26: Total Price | Y26: =C50 -> 18035.345
A27: Converting process | B27: 0.1 | C27: Based on the run length | D27: 0.05 | H27: KG | I27: =L14 -> 10.588436 | J27: =L16 -> 12.456983 | K27: =I27*$O$29 -> 12.38847 | L27: =J27*$O$29 -> 14.57467 | X27: Profit | Y27: =Y26-Y25 -> 18.655211
O28: Euro to dollar rate | Y28: =Y27/Y26 -> 0.0010343695
H29: Non Printed waste Assumption | O29: 1.17
I31: Eur | K31: USD
B32: Laminat Reel 607, 106 | C32: MOQ = 500KG | G32: =H14 -> 0.15 | I32: Cost | J32: Sale price | K32: Cost | L32: Sale price | P32: Shipment addition
B33: Laminat Reel 608 | C33: MOQ = 750KG | H33: ML | I33: =(Q8*(1+Q18)+SUM(Q9:Q11))/ROUNDDOWN((K3-30)/D3,0) -> 0.30615629 | J33: =I33/(1-$G$32) -> 0.36018388 | K33: =I33*$O$29 -> 0.35820286 | L33: =J33*$O$29 -> 0.42141513
B34: Laminat Reel 608W | C34: MOQ = 2000KG | H34: KG | I34: =$I33*$L22*K8/E3 -> 10.573083 | J34: =I34/(1-$G$32) -> 12.438921 | K34: =I34*$O$29 -> 12.370507 | L34: =J34*$O$29 -> 14.553537
B36: Laminate type | C36: Laminate819 | I36: =I33*800 -> 244.92504
B37: Food grade | C37: FG
B38: Quote by | C38: Ml | D38: Meter MOQ | E38: =IF(C36="Laminate608w",2000/N8*(E3/D3),IF(C36="Laminate608",750/N8*(E3/D3),500/N8*(E3/D3))) -> 16475.374
B39: Amount | C39: 50000 | D39: KG MOQ | E39: =IF(C36="Laminate608W",2000,IF(C36="Laminate608",750,500)) -> 500 | I39: QTY | J39: Cost | K39: Price
B40: Width of reel | C40: 260 | D40: Total KG | E40: =+L19 -> 1517.4163 | H40: Z10771.00023-000 | I40: 5000 | J40: 11.485134 | K40: 14.356417 | L40: =K40*I40 -> 71782.087
B41: Length limitation <50Kg (Y/N) | C41: Y | D41: (*) Min is 500 Meter | H41: Z10771.00023-000 | I41: =I40*2 -> 10000 | J41: =$I$34 -> 10.573083 | K41: =$J$34 -> 12.438921 | L41: =K41*I41 -> 124389.21 | M41: =K41/K40-1 -> -0.13356374
B42: Length Limit | D42: (*) Up to 1,150 width | H42: Z10771.00023-000 | I42: =I40*3 -> 15000 | J42: =$I$34 -> 10.573083 | K42: =$J$34 -> 12.438921 | L42: =K42*I42 -> 186583.81 | M42: =K42/K41-1 -> 0
...

Sheet Step by Step
B2: 📋 FILM PRICING LIST - STEP BY STEP GUIDE
B3: How to use the Film Pricing calculator
B5: 🔄 PRICING WORKFLOW
B7: STEP 1 | C7: → | D7: STEP 2 | E7: → | F7: STEP 3 | G7: → | H7: STEP 4 | I7: → | J7: STEP 5
B8: 📝 INPUT | D8: ⚙️ SPECS | F8: 💰 COSTS | H8: 📦 SHIP | J8: 💵 PRICE
B11: 📝 DETAILED STEPS
B13: Step | C13: Action | D13: Column | E13: Example | F13: Notes
B14: 1️⃣ | C14: Select Film Type | D14: A | E14: TIPA 302FG | F14: Dropdown list
B15: 2️⃣ | C15: Enter Width | D15: B | E15: 406 mm | F15: Width in mm
B16: 3️⃣ | C16: Enter Thickness | D16: C | E16: 20 µ | F16: Dropdown list
B17: 4️⃣ | C17: Enter Weight | D17: E | E17: 500 Kg | F17: Order qty (Kg)
B18: 5️⃣ | C18: Weight Override | D18: F | E18: 500 Kg | F18: Optional
B19: 6️⃣ | C19: Shipping Dest. | D19: S | E19: EU/USA | F19: Dropdown list
B20: 7️⃣ | C20: Review Price | D20: W | E20: Auto | F20: Final price/Kg
B21: 8️⃣ | C21: Compare Margins | D21: X+ | E21: 25%, 30% | F21: Multiple options
B24: ⚡ AUTO-CALCULATIONS
B26: Calculation | C26: Formula Logic
B27: Length (Mr) | C27: Weight ÷ (Width × Thickness × Density)
B28: Production Cost | C28: Hourly Rate × Production Time
B29: Total Cost | C29: RM + Production + Depreciation + Waste + Ship
B30: Sell Price | C30: Total Cost × (1 + Margin %)
B33: 💡 QUICK TIPS
B35: ✓ Use dropdowns to avoid typos
B36: ✓ Higher weight = lower cost/Kg (economies of scale)
B37: ✓ Compare margin columns for pricing options
B38: ✓ Density auto-fills based on Film Type

Sheet Converting- Marma & Bastin  (2)
M1: Important notes
A2: Supplier | B2: Bag Type | C2: Converting costs | D2: 25K pouches | E2: 25-50K | F2: 50-100K | G2: 100-250K | H2: 250-500K | I2: 500-1,000K | J2: 1,000K+ | M2: Converting costs include the packing costs - pallets , carton boxes , and does not include the zipper.
A3: Marma | B3: SUP with zipper | C3: 100 MM width | D3: 42.880992 | E3: 38.198066 | F3: 34.555789 | G3: 32.474488 | H3: 31.641968 | I3: 31.017578 | J3: 30.705383 | M3: *Price per 1000 pouch - EUR *
A4: Marma | B4: SUP with zipper | C4: 150 MM width | D4: 48.113821 | E4: 43.430894 | F4: 39.788618 | G4: 37.707317 | H4: 36.874797 | I4: 36.250407 | J4: 35.938211 | M4: 600 & 700 mm width- too wide, can't be done
A5: Marma | B5: SUP with zipper | C5: 200 MM width | D5: 54.713415 | E5: 50.030488 | F5: 46.388211 | G5: 44.306911 | H5: 43.47439 | I5: 42.85 | J5: 42.537805 | M5: 1.3 | N5: Bastin is highger than Marma by 30%- Shay's directive
A6: Marma | B6: SUP with zipper | C6: 300 MM width | D6: 65.816356 | E6: 61.133429 | F6: 57.491153 | G6: 55.409852 | H6: 54.577331 | I6: 53.952941 | J6: 53.640746
A7: Marma | B7: SUP with zipper | C7: 400 MM width | D7: 85.771107 | E7: 81.08818 | F7: 77.445904 | G7: 75.364603 | H7: 74.532083 | I7: 73.907692 | J7: 73.595497
A8: Marma | B8: SUP with zipper | C8: 500 MM width | D8: 116.34959 | E8: 111.66667 | F8: 108.02439 | G8: 105.94309 | H8: 105.11057 | I8: 104.48618 | J8: 104.17398
A9: Marma | B9: Zipper pouch | C9: 100 MM width | D9: 40.311989 | E9: 35.629062 | F9: 31.986785 | G9: 29.905485 | H9: 29.072964 | I9: 28.448574 | J9: 28.136379
A10: Marma | B10: Zipper pouch | C10: 150 MM width | D10: 45.133777 | E10: 40.45085 | F10: 36.808574 | G10: 34.727273 | H10: 33.894752 | I10: 33.270362 | J10: 32.958167
A11: Marma | B11: Zipper pouch | C11: 200 MM width | D11: 51.165743 | E11: 46.482816 | F11: 42.84054 | G11: 40.759239 | H11: 39.926718 | I11: 39.302328 | J11: 38.990133
A12: Marma | B12: Zipper pouch | C12: 300 MM width | D12: 61.433938 | E12: 56.751011 | F12: 53.108734 | G12: 51.027434 | H12: 50.194913 | I12: 49.570523 | J12: 49.258328
A13: Marma | B13: Zipper pouch | C13: 400 MM width | D13: 80.040252 | E13: 75.357326 | F13: 71.715049 | G13: 69.633748 | H13: 68.801228 | I13: 68.176838 | J13: 67.864643
A14: Marma | B14: Zipper pouch | C14: 500 MM width | D14: 108.07169 | E14: 103.38877 | F14: 99.746489 | G14: 97.665188 | H14: 96.832668 | I14: 96.208278 | J14: 95.896083
A15: Marma | B15: Open pouch | C15: 100 MM width | D15: 37.484035 | E15: 32.801109 | F15: 29.158832 | G15: 27.077531 | H15: 26.245011 | I15: 25.620621 | J15: 25.308426
A16: Marma | B16: Open pouch | C16: 150 MM width | D16: 41.767985 | E16: 37.085058 | F16: 33.442782 | G16: 31.361481 | H16: 30.528961 | I16: 29.904571 | J16: 29.592375
A17: Marma | B17: Open pouch | C17: 200 MM width | D17: 47.201844 | E17: 42.518917 | F17: 38.87664 | G17: 36.79534 | H17: 35.962819 | I17: 35.338429 | J17: 35.026234
... A20: Marma | B20: Open pouch | C20: 500 MM width | D20: 97.591356 | E20: 92.908429 | F20: 89.266153 | G20: 87.184852 | H20: 86.352332 | I20: 85.727942 | J20: 85.415746
A21: Bastin | B21: SUP with zipper | C21: 100 MM width | D21: =D3*$M$5 -> 55.74529 | E21: =E3*$M$5 -> 49.657485 | F21: =F3*$M$5 -> 44.922526 | G21: =G3*$M$5 -> 42.216835 | H21: =H3*$M$5 -> 41.134558 | I21: =I3*$M$5 -> 40.322851 | J21: =J3*$M$5 -> 39.916997
A22: Bastin | B22: SUP with zipper | C22: 150 MM width | D22: =D4*$M$5 -> 62.547967 | E22: =E4*$M$5 -> 56.460163 | F22: =F4*$M$5 -> 51.725203 | G22: =G4*$M$5 -> 49.019512 | H22: =H4*$M$5 -> 47.937236 | I22: =I4*$M$5 -> 47.125528 | J22: =J4*$M$5 -> 46.719675
A23: Bastin | B23: SUP with zipper | C23: 200 MM width | D23: =D5*$M$5 -> 71.127439 | E23: =E5*$M$5 -> 65.039634 | F23: =F5*$M$5 -> 60.304675 | G23: =G5*$M$5 -> 57.598984 | H23: =H5*$M$5 -> 56.516707 | I23: =I5*$M$5 -> 55.705 | J23: =J5*$M$5 -> 55.299146
A24: Bastin | B24: SUP with zipper | C24: 300 MM width | D24: =D6*$M$5 -> 85.561263 | E24: =E6*$M$5 -> 79.473458 | F24: =F6*$M$5 -> 74.738498 | G24: =G6*$M$5 -> 72.032807 | H24: =H6*$M$5 -> 70.950531 | I24: =I6*$M$5 -> 70.138824 | J24: =J6*$M$5 -> 69.73297
A25: Bastin | B25: SUP with zipper | C25: 400 MM width | D25: =D7*$M$5 -> 111.50244 | E25: =E7*$M$5 -> 105.41463 | F25: =F7*$M$5 -> 100.67967 | G25: =G7*$M$5 -> 97.973984 | H25: =H7*$M$5 -> 96.891707 | I25: =I7*$M$5 -> 96.08 | J25: =J7*$M$5 -> 95.674146
A26: Bastin | B26: SUP with zipper | C26: 500 MM width | D26: =D8*$M$5 -> 151.25447 | E26: =E8*$M$5 -> 145.16667 | F26: =F8*$M$5 -> 140.43171 | G26: =G8*$M$5 -> 137.72602 | H26: =H8*$M$5 -> 136.64374 | I26: =I8*$M$5 -> 135.83203 | J26: =J8*$M$5 -> 135.42618
A27: Bastin | B27: Zipper pouch | C27: 100 MM width | D27: =D9*$M$5 -> 52.405585 | E27: =E9*$M$5 -> 46.31778 | F27: =F9*$M$5 -> 41.582821 | G27: =G9*$M$5 -> 38.87713 | H27: =H9*$M$5 -> 37.794854 | I27: =I9*$M$5 -> 36.983146 | J27: =J9*$M$5 -> 36.577293
A28: Bastin | B28: Zipper pouch | C28: 150 MM width | D28: =D10*$M$5 -> 58.67391 | E28: =E10*$M$5 -> 52.586105 | F28: =F10*$M$5 -> 47.851146 | G28: =G10*$M$5 -> 45.145455 | H28: =H10*$M$5 -> 44.063178 | I28: =I10*$M$5 -> 43.251471 | J28: =J10*$M$5 -> 42.845617
A29: Bastin | B29: Zipper pouch | C29: 200 MM width | D29: =D11*$M$5 -> 66.515466 | E29: =E11*$M$5 -> 60.427661 | F29: =F11*$M$5 -> 55.692701 | G29: =G11*$M$5 -> 52.98701 | H29: =H11*$M$5 -> 51.904734 | I29: =I11*$M$5 -> 51.093027 | J29: =J11*$M$5 -> 50.687173
A30: Bastin | B30: Zipper pouch | C30: 300 MM width | D30: =D12*$M$5 -> 79.864119 | E30: =E12*$M$5 -> 73.776314 | F30: =F12*$M$5 -> 69.041355 | G30: =G12*$M$5 -> 66.335664 | H30: =H12*$M$5 -> 65.253387 | I30: =I12*$M$5 -> 64.44168 | J30: =J12*$M$5 -> 64.035826
A31: Bastin | B31: Zipper pouch | C31: 400 MM width | D31: =D13*$M$5 -> 104.05233 | E31: =E13*$M$5 -> 97.964523 | F31: =F13*$M$5 -> 93.229564 | G31: =G13*$M$5 -> 90.523873 | H31: =H13*$M$5 -> 89.441596 | I31: =I13*$M$5 -> 88.629889 | J31: =J13*$M$5 -> 88.224035
A32: Bastin | B32: Zipper pouch | C32: 500 MM width | D32: =D14*$M$5 -> 140.4932 | E32: =E14*$M$5 -> 134.4054 | F32: =F14*$M$5 -> 129.67044 | G32: =G14*$M$5 -> 126.96475 | H32: =H14*$M$5 -> 125.88247 | I32: =I14*$M$5 -> 125.07076 | J32: =J14*$M$5 -> 124.66491
... A38: Bastin | B38: Open pouch | C38: 500 MM width | D38: =D20*$M$5 -> 126.86876 | E38: =E20*$M$5 -> 120.78096 | F38: =F20*$M$5 -> 116.046 | G38: =G20*$M$5 -> 113.34031 | H38: =H20*$M$5 -> 112.25803 | I38: =I20*$M$5 -> 111.44632 | J38: =J20*$M$5 -> 111.04047

Sheet Lmntn & Prntng- Marma & Bas (2)
A2: Supplier | B2: Width | C2: Per film cost costs: | D2: up to 3k Meters (*) ( **) | E2: 3-10K | F2: 10-25K | G2: 25K-50 | H2: 50-100K | I2: 100-250K | J2: 250-500K | K2: 500K+ | M2: Important notes
A3: MARMA | B3: linear meters (760 width)- EUR/1000m | C3: Lamination First pass | D3: 83.38 | E3: 74.38 | F3: 65.38 | G3: 61.78 | H3: 60.58 | I3: 59.98 | J3: 59.62 | K3: 59.39 | M3: 1.3 | N3: Bastin prices are 30% higher than Marma for lamination
B4: linear meters (760 width)- EUR/1000m | C4: Lamination First pass (120 m/m) | D4: 116.73 | E4: 104.13 | F4: 91.53 | G4: 86.49 | H4: 84.81 | I4: 83.97 | J4: 83.46 | K4: 83.14 | M4: 1.5 | N4: Bastin prices are 50% higher than Marma for printing
B5: linear meters (760 width)- EUR/1000m | C5: Lamination First pass (90 m/m) | D5: 149.15 | E5: 133.05 | F5: 116.95 | G5: 110.51 | H5: 108.36 | I5: 107.29 | J5: 106.64 | K5: 106.24
B6: linear meters (760 width)- EUR/1000m | C6: Lamination Second pass
B7: linear meters (760 width)- EUR/1000m | C7: Printing (1-2 colors)*** | D7: 196.44 | E7: 154.37 | F7: 112.29 | G7: 95.46 | H7: 89.85 | I7: 87.05 | J7: 85.36 | K7: 84.3
B8: linear meters (760 width)- EUR/1000m | C8: Printing (3-4 colors)*** | D8: 227.42 | E8: 177.02 | F8: 126.62 | G8: 106.46 | H8: 99.74 | I8: 96.38 | J8: 94.36 | K8: 93.09
B9: linear meters (760 width)- EUR/1000m | C9: Printing (5-8 colors)*** | D9: 276.21 | E9: 209.16 | F9: 142.11 | G9: 115.29 | H9: 106.35 | I9: 101.88 | J9: 99.2 | K9: 97.5
B10: linear meters (760 width)- EUR/1000m | C10: Slitting | D10: 34.92 | E10: 30.42 | F10: 25.92 | G10: 24.12 | H10: 23.52 | I10: 23.22 | J10: 23.04 | K10: 22.92
B11: linear meters (1220 width)- EUR/1000m | C11: Lamination First pass | D11: 83.375 | E11: 74.38 | F11: 65.38 | G11: 61.78 | H11: 60.58 | I11: 59.98 | J11: 59.62 | K11: 59.39
B12: linear meters (1220 width)- EUR/1000m | C12: Lamination First pass (120 m/m) | D12: 116.73 | E12: 104.13 | F12: 91.53 | G12: 86.49 | H12: 84.81 | I12: 83.97 | J12: 83.46 | K12: 83.14
B13: linear meters (1220 width)- EUR/1000m | C13: Lamination First pass (90 m/m) | D13: 149.15 | E13: 133.05 | F13: 116.95 | G13: 110.51 | H13: 108.36 | I13: 107.29 | J13: 106.64 | K13: 106.24
B14: linear meters (1220 width)- EUR/1000m | C14: Lamination Second pass
B15: linear meters (1220 width)- EUR/1000m | C15: Printing (1-2 colors)*** | D15: 215.03702 | E15: 172.96202 | F15: 130.88702 | G15: 114.05702 | H15: 108.44702 | I15: 105.64202 | J15: 103.95902 | K15: 102.89312
B16: linear meters (1220 width)- EUR/1000m | C16: Printing (3-4 colors)*** | D16: 251.32802 | E16: 200.92802 | F16: 150.52802 | G16: 130.36802 | H16: 123.64802 | I16: 120.28802 | J16: 118.27202 | K16: 116.99522
B17: linear meters (1220 width)- EUR/1000m | C17: Printing (5-8 colors)*** | D17: 302.77352 | E17: 235.72352 | F17: 168.67352 | G17: 141.85352 | H17: 132.91352 | I17: 128.44352 | J17: 125.76152 | K17: 124.06292
B18: linear meters (1220 width)- EUR/1000m | C18: Slitting | D18: 34.916667 | E18: 30.416667 | F18: 25.916667 | G18: 24.116667 | H18: 23.516667 | I18: 23.216667 | J18: 23.036667 | K18: 22.922667
A19: Bastin | B19: linear meters (760 width)- EUR/1000m | C19: Lamination First pass | D19: =D3*$M$3 -> 108.394 | E19: =E3*$M$3 -> 96.694 | F19: =F3*$M$3 -> 84.994 | G19: =G3*$M$3 -> 80.314 | H19: =H3*$M$3 -> 78.754 | I19: =I3*$M$3 -> 77.974 | J19: =J3*$M$3 -> 77.506 | K19: =K3*$M$3 -> 77.207
B20: linear meters (760 width)- EUR/1000m | C20: Lamination First pass (120 m/m) | D20: =D4*$M$3 -> 151.749 | E20: =E4*$M$3 -> 135.369 | F20: =F4*$M$3 -> 118.989 | G20: =G4*$M$3 -> 112.437 | H20: =H4*$M$3 -> 110.253 | I20: =I4*$M$3 -> 109.161 | J20: =J4*$M$3 -> 108.498 | K20: =K4*$M$3 -> 108.082
B21: linear meters (760 width)- EUR/1000m | C21: Lamination First pass (90 m/m) | D21: =D5*$M$3 -> 193.895 | E21: =E5*$M$3 -> 172.965 | F21: =F5*$M$3 -> 152.035 | G21: =G5*$M$3 -> 143.663 | H21: =H5*$M$3 -> 140.868 | I21: =I5*$M$3 -> 139.477 | J21: =J5*$M$3 -> 138.632 | K21: =K5*$M$3 -> 138.112
B22: linear meters (760 width)- EUR/1000m | C22: Lamination Second pass | D22: =D6*$M$3 -> 0 | E22: =E6*$M$3 -> 0 | F22: =F6*$M$3 -> 0 | G22: =G6*$M$3 -> 0 | H22: =H6*$M$3 -> 0 | I22: =I6*$M$3 -> 0 | J22: =J6*$M$3 -> 0 | K22: =K6*$M$3 -> 0
B23: linear meters (760 width)- EUR/1000m | C23: Printing (1-2 colors)*** | D23: =D7*$M$4 -> 294.66 | E23: =E7*$M$4 -> 231.555 | F23: =F7*$M$4 -> 168.435 | G23: =G7*$M$4 -> 143.19 | H23: =H7*$M$4 -> 134.775 | I23: =I7*$M$4 -> 130.575 | J23: =J7*$M$4 -> 128.04 | K23: =K7*$M$4 -> 126.45
B24: linear meters (760 width)- EUR/1000m | C24: Printing (3-4 colors)*** | D24: =D8*$M$4 -> 341.13 | E24: =E8*$M$4 -> 265.53 | F24: =F8*$M$4 -> 189.93 | G24: =G8*$M$4 -> 159.69 | H24: =H8*$M$4 -> 149.61 | I24: =I8*$M$4 -> 144.57 | J24: =J8*$M$4 -> 141.54 | K24: =K8*$M$4 -> 139.635
B25: linear meters (760 width)- EUR/1000m | C25: Printing (5-8 colors)*** | D25: =D9*$M$4 -> 414.315 | E25: =E9*$M$4 -> 313.74 | F25: =F9*$M$4 -> 213.165 | G25: =G9*$M$4 -> 172.935 | H25: =H9*$M$4 -> 159.525 | I25: =I9*$M$4 -> 152.82 | J25: =J9*$M$4 -> 148.8 | K25: =K9*$M$4 -> 146.25
B26: linear meters (760 width)- EUR/1000m | C26: Slitting | D26: =D10*$M$3 -> 45.396 | E26: =E10*$M$3 -> 39.546 | F26: =F10*$M$3 -> 33.696 | G26: =G10*$M$3 -> 31.356 | H26: =H10*$M$3 -> 30.576 | I26: =I10*$M$3 -> 30.186 | J26: =J10*$M$3 -> 29.952 | K26: =K10*$M$3 -> 29.796
B27: linear meters (1220 width)- EUR/1000m | C27: Lamination First pass | D27: =D11*$M$3 -> 108.3875 | E27: =E11*$M$3 -> 96.694 | F27: =F11*$M$3 -> 84.994 | G27: =G11*$M$3 -> 80.314 | H27: =H11*$M$3 -> 78.754 | I27: =I11*$M$3 -> 77.974 | J27: =J11*$M$3 -> 77.506 | K27: =K11*$M$3 -> 77.207
B28: linear meters (1220 width)- EUR/1000m | C28: Lamination First pass (120 m/m) | D28: =D12*$M$3 -> 151.749 | E28: =E12*$M$3 -> 135.369 | F28: =F12*$M$3 -> 118.989 | G28: =G12*$M$3 -> 112.437 | H28: =H12*$M$3 -> 110.253 | I28: =I12*$M$3 -> 109.161 | J28: =J12*$M$3 -> 108.498 | K28: =K12*$M$3 -> 108.082
B29: linear meters (1220 width)- EUR/1000m | C29: Lamination First pass (90 m/m) | D29: =D13*$M$3 -> 193.895 | E29: =E13*$M$3 -> 172.965 | F29: =F13*$M$3 -> 152.035 | G29: =G13*$M$3 -> 143.663 | H29: =H13*$M$3 -> 140.868 | I29: =I13*$M$3 -> 139.477 | J29: =J13*$M$3 -> 138.632 | K29: =K13*$M$3 -> 138.112
B30: linear meters (1220 width)- EUR/1000m | C30: Lamination Second pass | D30: =D14*$M$3 -> 0 | E30: =E14*$M$3 -> 0 | F30: =F14*$M$3 -> 0 | G30: =G14*$M$3 -> 0 | H30: =H14*$M$3 -> 0 | I30: =I14*$M$3 -> 0 | J30: =J14*$M$3 -> 0 | K30: =K14*$M$3 -> 0
B31: linear meters (1220 width)- EUR/1000m | C31: Printing (1-2 colors)*** | D31: =D15*$M$4 -> 322.55553 | E31: =E15*$M$4 -> 259.44303 | F31: =F15*$M$4 -> 196.33053 | G31: =G15*$M$4 -> 171.08553 | H31: =H15*$M$4 -> 162.67053 | I31: =I15*$M$4 -> 158.46303 | J31: =J15*$M$4 -> 155.93853 | K31: =K15*$M$4 -> 154.33968
B32: linear meters (1220 width)- EUR/1000m | C32: Printing (3-4 colors)*** | D32: =D16*$M$4 -> 376.99203 | E32: =E16*$M$4 -> 301.39203 | F32: =F16*$M$4 -> 225.79203 | G32: =G16*$M$4 -> 195.55203 | H32: =H16*$M$4 -> 185.47203 | I32: =I16*$M$4 -> 180.43203 | J32: =J16*$M$4 -> 177.40803 | K32: =K16*$M$4 -> 175.49283
B33: linear meters (1220 width)- EUR/1000m | C33: Printing (5-8 colors)*** | D33: =D17*$M$4 -> 454.16028 | E33: =E17*$M$4 -> 353.58528 | F33: =F17*$M$4 -> 253.01028 | G33: =G17*$M$4 -> 212.78028 | H33: =H17*$M$4 -> 199.37028 | I33: =I17*$M$4 -> 192.66528 | J33: =J17*$M$4 -> 188.64228 | K33: =K17*$M$4 -> 186.09438
B34: linear meters (1220 width)- EUR/1000m | C34: Slitting | D34: =D18*$M$3 -> 45.391667 | E34: =E18*$M$3 -> 39.541667 | F34: =F18*$M$3 -> 33.691667 | G34: =G18*$M$3 -> 31.351667 | H34: =H18*$M$3 -> 30.571667 | I34: =I18*$M$3 -> 30.181667 | J34: =J18*$M$3 -> 29.947667 | K34: =K18*$M$3 -> 29.799467

Sheet Laminates (2)
A1: From Calculator | B1: From Calculator | C1: Dependent | F1: From Calculator | G1: Calculation | H1: From Calculator | I1: From Calculator | J1: Dependent on Laminate | K1: Calculation | L1: Calculation | M1: Calculation | N1: Calculation | O1: From Calculator | P1: Calculation | Q1: From Calculator | R1: Dependent on Length | S1: Dependent on Length | T1: Calculation | U1: Dependent on Length | V1: Calculation | W1: Calculation | Y1: Calculation | Z1: checking purposes | AA1: From Calculator | AB1: Calculation | AC1: Calculation | AG1: 📊 GROSS PROFIT | AH1: 0.15 | AK1: 📊 GROSS PROFIT | AL1: 0.15 | AO1: 📊 GROSS PROFIT | AP1: 0.15
A2: Amount | B2: Laminate | C2: Laminate structure | D2: Width of reel asked | E2: Width of reel used | F2: Length of impression | G2: Laminate length (m) width asked | H2: PR/ NonPR | I2: No of colors | J2: Lamination Width (mm) | K2: Thickness (µ) | L2: Density | M2: Weight (kg) | N2: Raw material Cost | O2: Shipping Terms | P2: Shipment costs | Q2: Producer | R2: Lamination | S2: Printing | T2: Printing per KG | U2: Slitting | V2: Waste | W2: Printing waste | X2: Cost (€) | Y2: Total Cost per KG | Z2: Cost Per KG (€) | AA2: No. of SKUs | AB2: IMP / SKU | AC2: NK ratio | AG2: ="📊 LAMINATE CALCULATOR 1-"&AH3&" Laminate" -> 📊 LAMINATE CALCULATOR 1-428 Laminate | AK2: ="📊 LAMINATE CALCULATOR 2-"&AL3&" Laminate" -> 📊 LAMINATE CALCULATOR 2-428 Laminate | AO2: ="📊 LAMINATE CALCULATOR 3-"&AP3&" Laminate" -> 📊 LAMINATE CALCULATOR 3-428 Laminate
A3: =IF(AH13="By Length",IF(AH14<>"",IFERROR(AH14*$M$8*($D3/$J3),""),""),IF(OR(AH13="By Imp",AH13="IMP"),IFERROR(AH41*$M$8*($D3/$J3),""),IF(AH6="","",AH6))) -> 503.51513 | B3: =AH3 -> 428 | C3: {=IFERROR(_xlfn.LET(_xlpm.lam,TEXT(B3,"0"),_xlpm.thick,AH4,_xlfn.TAKE(_xlfn._xlws.FILTER([6]HELPER!$BW$2:$BW$250,(TEXT([6]HELPER!$BZ$2:$BZ$250,"0")=_xlpm.lam)*([6]HELPER!$CC$2:$CC$250=_xlpm.thick)*([6]HELPER!$BW$2:$BW$250<>""),"No match"),6)),"")} -> NK | D3: =AH5 -> 352 | E3: =IF(D3="","",_xlfn.LET(_xlpm.cap,IF($Q3="Quantum",760,1220),IF(D3+50>_xlpm.cap,"ERROR: Lamination Width > "&_xlpm.cap,D3*MAX(1,MIN(MAX(2,INT(900/D3)),INT((_xlpm.cap-50)/D3)))))) -> 704 | G3: =IF(OR(AH13="IMP",AH13="By Imp",AH13="By Length"),IFERROR(AH16,""),IFERROR(IF(OR(A3="",A3=0,$D3="",$D3=0,$J3="",$M$8="",$M$8=0,A3<=5),"",(A3-5)/$M$8*($J3/$D3)),"")) -> 13939.2 | H3: =AH7 -> Printed | I3: =IF(H3="Not Printed",0,AH8) -> 3-4 | J3: =IF(C3="","",$E$3+16) -> 720 | K3: {=_xlfn.LET(_xlpm.baseThick,IFERROR(INDEX([6]HELPER!$BX$2:$BX$250,MATCH(1,(TEXT([6]HELPER!$BZ$2:$BZ$250,"0")=TEXT($B$3,"0"))*([6]HELPER!$CC$2:$CC$250=$AH$4)*([6]HELPER!$BW$2:$BW$250=C3),0)),""),IF(_xlpm.baseThick="","",_xlpm.baseThick))} -> 23 | L3: =IFERROR(VLOOKUP(C3,[6]HELPER!$AP$1:$AQ$25,2,FALSE),"") -> 1.44 | M3: =IF(C3="","",IF(ISNUMBER(SEARCH("paper",C3)),42/1000*(J3/1000),IF(OR(L3="",L3=0),"",L3*1000*(K3/1000000)*(J3/1000)))) -> 0.0238464 | N3: {=IF($C3="","",_xlfn.LET( _xlpm.mat,TRIM($C3), _xlpm.matKey,UPPER(SUBSTITUTE(_xlpm.mat," ","")), _xlpm.pr,IFERROR(LOOKUP(2,1/($H$3:H3<>""),$H$3:H3),""), _xlpm.widthActual,IFERROR(LOOKUP(2,1/($E$3:E3<>""),$E$3:E3),$E3), _xlpm.euShip,IFERROR([6]HELPER!$AH$3,0), _xlpm.metSetup,IFERROR([6]HELPER!$CH$2,0), _xlpm.filmNames,[6]!Table1[Film Type], _xlpm.filmCosts,[6]!Table1[For Laminates calculation purposes], _xlpm.printCosts,[6]!Table1[Printing], _xlpm.printWaste,[6]!Table1[Printing Waste], _xlpm.filmCost,IF(LEFT(_xlpm.mat,4)="TIPA",IFERROR(IF(_xlpm.pr="Not Printed",MIN(_xlfn._xlws.FILTER(_xlpm.filmCosts,(UPPER(SUBSTITUTE(_xlpm.filmNames," ",""))=_xlpm.matKey)*(_xlpm.printCosts=0)*(_xlpm.printWaste=0)*(_xlpm.filmCosts>0))),INDEX(_xlfn._xlws.FILTER(_xlpm.filmCosts,(UPPER(SUBSTITUTE(_xlpm.filmNames," ",""))=_xlpm.matKey)*(_xlpm.filmCosts>0)),1)),""),""), _xlpm.summaryNames,"", _xlpm.summaryThick,"", _xlpm.summaryCosts,"", _xlpm.summaryCost,IF(LEFT(_xlpm.mat,4)="TIPA",IFERROR(IF(_xlpm.pr="Not Printed",MIN(_xlfn._xlws.FILTER(_xlpm.summaryCosts,(UPPER(SUBSTITUTE(_xlpm.summaryNames," ",""))=_xlpm.matKey)*(_xlpm.summaryThick=$K3)*(_xlpm.summaryCosts>0))),INDEX(_xlfn._xlws.FILTER(_xlpm.summaryCosts,(UPPER(SUBSTITUTE(_xlpm.summaryNames," ",""))=_xlpm.matKey)*(_xlpm.summaryThick=$K3)*(_xlpm.summaryCosts>0)),1)),""),""), _xlpm.finalFilmCost,IF(_xlpm.filmCost<>"",_xlpm.filmCost,_xlpm.summaryCost), _xlpm.metFilmCost,IFERROR(INDEX(_xlpm.filmCosts,MATCH("TIPA 312 MFG",_xlpm.filmNames,0)),INDEX(_xlpm.filmCosts,1)), _xlpm.tipa312MfgCost,IFERROR(IF(_xlpm.pr="Not Printed",MIN(_xlfn._xlws.FILTER(_xlpm.filmCosts,(UPPER(SUBSTITUTE(_xlpm.filmNames," ",""))="TIPA312MFG")*(_xlpm.printCosts=0)*(_xlpm.printWaste=0)*(_xlpm.filmCosts>0))),INDEX(_xlfn._xlws.FILTER(_xlpm.filmCosts,(UPPER(SUBSTITUTE(_xlpm.filmNames," ",""))="TIPA312MFG")*(_xlpm.filmCosts>0)),1)),0), _xlpm.metluxCost,IFERROR(INDEX([6]HELPER!$E$2:$E$32,MATCH(TRUE,TRIM([6]HELPER!$A$2:$A$32)="MET LUX",0)),IFERROR(INDEX([6]HELPER!$E$2:$E$32,MATCH(TRUE,TRIM([6]HELPER!$B$2:$B$32)="MET LUX",0)),IFERROR(INDEX([6]HELPER!$E$2:$E$32,MATCH(TRUE,TRIM([6]HELPER!$C$2:$C$32)="MET LUX",0)),IFERROR(INDEX([6]HELPER!$E$2:$E$32,MATCH(TRUE,TRIM([6]HELPER!$D$2:$D$32)="MET LUX",0)),0)))), _xlpm.helperCost,IFERROR(INDEX([6]HELPER!$E$2:$E$32,MATCH(TRUE,TRIM([6]HELPER!$A$2:$A$32)=_xlpm.mat,0)),IFERROR(INDEX([6]HELPER!$E$2:$E$32,MATCH(TRUE,TRIM([6]HELPER!$B$2:$B$32)=_xlpm.mat,0)),IFERROR(INDEX([6]HELPER!$E$2:$E$32,MATCH(TRUE,TRIM([6]HELPER!$C$2:$C$32)=_xlpm.mat,0)),IFERROR(INDEX([6]HELPER!$E$2:$E$32,MATCH(TRUE,TRIM([6]HELPER!$D$2:$D$32)=_xlpm.mat,0)),"")))), _xlpm.specialCost,IFERROR(_xlfn.XLOOKUP(_xlpm.mat,[6]HELPER!$CK$2:$CK$105,[6]HELPER!$CO$2:$CO$105,""),""), _xlpm.nkHelperCost,IFERROR(INDEX([6]HELPER!$E$2:$E$32,MATCH(TRUE,TRIM([6]HELPER!$A$2:$A$32)="NK",0)),IFERROR(INDEX([6]HELPER!$E$2:$E$32,MATCH(TRUE,TRIM([6]HELPER!$B$2:$B$32)="NK",0)),IFERROR(INDEX([6]HELPER!$E$2:$E$32,MATCH(TRUE,TRIM([6]HELPER!$C$2:$C$32)="NK",0)),IFERROR(INDEX([6]HELPER!$E$2:$E$32,MATCH(TRUE,TRIM([6]HELPER!$D$2:$D$32)="NK",0)),0)))), _xlpm.baseCost,IF(LEFT(_xlpm.mat,4)="TIPA",IF(_xlpm.finalFilmCost<>"",_xlpm.finalFilmCost,_xlpm.specialCost),_xlpm.helperCost), _xlpm.rawResult,IF(OR(_xlpm.mat="NK",_xlpm.mat="NKR",_xlpm.mat="NVS"),_xlpm.nkHelperCost,IF(_xlpm.baseCost="","",IF(OR(_xlpm.finalFilmCost<>"",LEFT(_xlpm.mat,4)="TIPA"),_xlpm.baseCost,_xlpm.baseCost+_xlpm.euShip))), _xlpm.upliftFilm,ISNUMBER(MATCH(_xlpm.matKey,{"TIPA312MET";"TIPA302FG";"TIPA302FGW";"TIPA306M";"TIPA306W";"TIPA312MFG";"TIPA312MFGW"},0)), _xlpm.rawResult ))} -> 7.95 | O3: =AH11 -> EXW | P3: =IF(OR(C3="",A$3<=0),"",IFERROR(IF(O$3="Europe to US",IF(A$3<500,10,IF(A$3<1000,8,IF(A$3<2500,6,IF(A$3<5000,5,4)))),VLOOKUP(O$3,[6]HELPER!$AF$2:$AH$3,3,FALSE)),0)) -> 0 | Q3: =AH12 -> Marma | R3: {=IF(OR($Q3="",$G3=""),"",IF($J3>IF($Q3="Quantum",760,1220),"Error! lamination width exceeds supplier maximum",_xlfn.LET(_xlpm.struct,$C$3:$C$8,_xlpm.realLayers,SUMPRODUCT(--(_xlpm.struct<>""),--ISERROR(SEARCH("EPOTAL",_xlpm.struct&"")),--ISERROR(SEARCH("BASONAT",_xlpm.struct&"")),--ISERROR(SEARCH("ADH",_xlpm.struct&"")),--ISERROR(SEARCH("HARDENER",_xlpm.struct&""))),_xlpm.lamSteps,MAX(0,_xlpm.realLayers-1),_xlpm.len,$G3,_xlpm.colNum,IF(_xlpm.len<3000,1,IF(_xlpm.len<10000,2,IF(_xlpm.len<25000,3,IF(_xlpm.len<50000,4,IF(_xlpm.len<100000,5,IF(_xlpm.len<250000,6,7)))))),_xlpm.widthRow,IF($E3<900,0,5),_xlpm.supplierRow,IF($Q3="Marma",3,IF(OR($Q3="Bastin",$Q3="Quantum"),13,0)),_xlpm.baseRate,IF(_xlpm.supplierRow=0,"",INDEX('[6]Lmntn & Prntng- Marma & Bastin '!$D$1:$K$22,_xlpm.supplierRow+_xlpm.widthRow,_xlpm.colNum)),IF(_xlpm.realLayers=0,"",_xlpm.baseRate*_xlpm.lamSteps))))} -> 0.18306 | S3: {=IF($Q3="Quantum",IF(OR($Q3="",$I3=0,$I3="0"),"",IF($J3>IF($Q3="Quantum",760,1220),"Error! lamination width exceeds supplier maximum",IF($E3>1200,"Data is missing",_xlfn.LET(_xlpm.len,$G3,_xlpm.colors,$I3,_xlpm.qWidth,IF($E3<=450,450,IF($E3<=760,760,1200)),_xlpm.band,IF(_xlpm.colors=1,"1",IF(OR(_xlpm.colors=2,_xlpm.colors=3),"2-3",IF(OR(_xlpm.colors=4,_xlpm.colors=5),"4-5","6-8"))),_xlpm.widths,'[6]Digital_per_meter- Quantum'!$A$32:$A$91,_xlpm.bands,'[6]Digital_per_meter- Quantum'!$C$32:$C$91,_xlpm.meters,'[6]Digital_per_meter- Quantum'!$D$32:$D$91,_xlpm.rates,'[6]Digital_per_meter- Quantum'!$H$32:$H$91,_xlpm.targetM,IFERROR(MIN(_xlfn._xlws.FILTER(_xlpm.meters,(_xlpm.widths=_xlpm.qWidth)*(_xlpm.bands=_xlpm.band)*(_xlpm.meters>=_xlpm.len))),MAX(_xlfn._xlws.FILTER(_xlpm.meters,(_xlpm.widths=_xlpm.qWidth)*(_xlpm.bands=_xlpm.band)))),INDEX(_xlpm.rates,_xlfn.XMATCH(1,(_xlpm.widths=_xlpm.qWidth)*(_xlpm.bands=_xlpm.band)*(_xlpm.meters=_xlpm.targetM),0))/[6]HELPER!$AK$2)))),IF(OR($Q3="",$I3=0,$I3="0"),"",IF($J3>IF($Q3="Quantum",760,1220),"Error! lamination width exceeds supplier maximum",_xlfn.LET(_xlpm.len,$AH$22,_xlpm.colors,$I3,_xlpm.colNum,IF(_xlpm.len<3000,1,IF(_xlpm.len<10000,2,IF(_xlpm.len<25000,3,IF(_xlpm.len<50000,4,IF(_xlpm.len<100000,5,IF(_xlpm.len<250000,6,IF(_xlpm.len<500000,7,8))))))),_xlpm.widthRow,IF($E3<900,0,5),_xlpm.colorOffset,IF(OR(_xlpm.colors=1,_xlpm.colors=2,_xlpm.colors="1-2"),1,IF(OR(_xlpm.colors=3,_xlpm.colors=4,_xlpm.colors="3-4"),2,IF(OR(_xlpm.colors>=5,_xlpm.colors="5-6",_xlpm.colors="5-8"),3,0))),_xlpm.supplierRow,IF($Q3="Marma",3,IF($Q3="Bastin",13,0)),IF(OR(_xlpm.supplierRow=0,_xlpm.colorOffset=0),"",INDEX('[6]Lmntn & Prntng- Marma & Bastin '!$D$1:$K$22,_xlpm.supplierRow+_xlpm.widthRow+_xlpm.colorOffset,_xlpm.colNum))))))} -> 0.17702 | T3: =IF(OR($S3="",$K3=""),"",IFERROR($S3*(1/$M$8)*($J3/($D3*MAX(1,ROUNDDOWN(760/$D3,0)))),"")) -> 2.450291 | U3: {=IF($Q3="","",IF($J3>IF($Q3="Quantum",760,1220),"Error! lamination width exceeds supplier maximum",_xlfn.LET(_xlpm.len,$G3,_xlpm.colNum,IF(_xlpm.len<3000,1,IF(_xlpm.len<10000,2,IF(_xlpm.len<25000,3,IF(_xlpm.len<50000,4,IF(_xlpm.len<100000,5,IF(_xlpm.len<250000,6,7)))))),_xlpm.widthRow,IF($E3<900,0,5),_xlpm.supplierRow,IF($Q3="Marma",7,IF(OR($Q3="Bastin",$Q3="Quantum"),17,0)),IF(_xlpm.supplierRow=0,"",INDEX('[6]Lmntn & Prntng- Marma & Bastin '!$D$1:$K$22,_xlpm.supplierRow+_xlpm.widthRow,_xlpm.colNum)))))} -> 0.02592 | V3: =IFERROR(IF(AH23="","",IF($K8>31,(5%+250/$G$3)*AH23,VLOOKUP($K8,[6]HELPER!$BH$3:$BI$5,2,TRUE)*AH23)),"") -> 0.54781005 | W3: =IF(OR($H3<>"Printed",$I3=0,$I3="0"),0,IFERROR(AH23*0.028,0)+IFERROR(AH44,0)) -> 1.0517187 | X3: =IF($K3="","",IFERROR($M3*($N3+$P3),"")) -> 0.18957888 | Y3: =IFERROR((SUM(X3:X8)+SUM(R3:S3,U3))*(1/M8)*(J3/E3)+V3+W3,"") -> 15.006232 | Z3: =IF($M3="","",IFERROR(($N3+$P3)*$M3/$M$8,"")) -> 2.5658156 | AA3: =AH9 -> 1 | AB3: =IF(OR(AH13="IMP",AH13="By Imp"),IFERROR(AH14/AA3,""),"") -> 52800 | AC3: =AH43 -> 0.33333333 | AG3: 🏷️ Laminate | AH3: 428 | AK3: 🏷️ Laminate | AL3: 428 | AO3: 🏷️ Laminate | AP3: 428
C4: TIPA 312 MET | J4: =IF(C4="","",$E$3+16) -> 720 | K4: {=_xlfn.LET(_xlpm.baseThick,IFERROR(INDEX([6]HELPER!$BX$2:$BX$250,MATCH(1,(TEXT([6]HELPER!$BZ$2:$BZ$250,"0")=TEXT($B$3,"0"))*([6]HELPER!$CC$2:$CC$250=$AH$4)*([6]HELPER!$BW$2:$BW$250=C4),0)),""),IF(_xlpm.baseThick="","",_xlpm.baseThick))} -> 25 | L4: =IFERROR(VLOOKUP(C4,[6]HELPER!$AP$1:$AQ$25,2,FALSE),"") -> 1.25 | M4: =IF(C4="","",IF(ISNUMBER(SEARCH("paper",C4)),42/1000*(J4/1000),IF(OR(L4="",L4=0),"",L4*1000*(K4/1000000)*(J4/1000)))) -> 0.0225 | N4: {=IF($C4="","",_xlfn.LET( _xlpm.mat,TRIM($C4), _xlpm.matKey,UPPER(SUBSTITUTE(_xlpm.mat," ","")), _xlpm.pr,IFERROR(LOOKUP(2,1/($H$3:H4<>""),$H$3:H4),""), _xlpm.widthActual,IFERROR(LOOKUP(2,1/($E$3:E4<>""),$E$3:E4),$E4), _xlpm.euShip,IFERROR([6]HELPER!$AH$3,0), _xlpm.metSetup,IFERROR([6]HELPER!$CH$2,0), _xlpm.filmNames,[6]!Table1[Film Type], _xlpm.filmCosts,[6]!Table1[For Laminates calculation purposes], _xlpm.printCosts,[6]!Table1[Printing], _xlpm.printWaste,[6]!Table1[Printing Waste], _xlpm.filmCost,IF(LEFT(_xlpm.mat,4)="TIPA",IFERROR(IF(_xlpm.pr="Not Printed",MIN(_xlfn._xlws.FILTER(_xlpm.filmCosts,(UPPER(SUBSTITUTE(_xlpm.filmNames," ",""))=_xlpm.matKey)*(_xlpm.printCosts=0)*(_xlpm.printWaste=0)*(_xlpm.filmCosts>0))),INDEX(_xlfn._xlws.FILTER(_xlpm.filmCosts,(UPPER(SUBSTITUTE(_xlpm.filmNames," ",""))=_xlpm.matKey)*(_xlpm.filmCosts>0)),1)),""),""), _xlpm.summaryNames,"", _xlpm.summaryThick,"", _xlpm.summaryCosts,"", _xlpm.summaryCost,IF(LEFT(_xlpm.mat,4)="TIPA",IFERROR(IF(_xlpm.pr="Not Printed",MIN(_xlfn._xlws.FILTER(_xlpm.summaryCosts,(UPPER(SUBSTITUTE(_xlpm.summaryNames," ",""))=_xlpm.matKey)*(_xlpm.summaryThick=$K4)*(_xlpm.summaryCosts>0))),INDEX(_xlfn._xlws.FILTER(_xlpm.summaryCosts,(UPPER(SUBSTITUTE(_xlpm.summaryNames," ",""))=_xlpm.matKey)*(_xlpm.summaryThick=$K4)*(_xlpm.summaryCosts>0)),1)),""),""), _xlpm.finalFilmCost,IF(_xlpm.filmCost<>"",_xlpm.filmCost,_xlpm.summaryCost), _xlpm.metFilmCost,IFERROR(INDEX(_xlpm.filmCosts,MATCH("TIPA 312 MFG",_xlpm.filmNames,0)),INDEX(_xlpm.filmCosts,1)), _xlpm.tipa312MfgCost,IFERROR(IF(_xlpm.pr="Not Printed",MIN(_xlfn._xlws.FILTER(_xlpm.filmCosts,(UPPER(SUBSTITUTE(_xlpm.filmNames," ",""))="TIPA312MFG")*(_xlpm.printCosts=0)*(_xlpm.printWaste=0)*(_xlpm.filmCosts>0))),INDEX(_xlfn._xlws.FILTER(_xlpm.filmCosts,(UPPER(SUBSTITUTE(_xlpm.filmNames," ",""))="TIPA312MFG")*(_xlpm.filmCosts>0)),1)),0), _xlpm.metluxCost,IFERROR(INDEX([6]HELPER!$E$2:$E$32,MATCH(TRUE,TRIM([6]HELPER!$A$2:$A$32)="MET LUX",0)),IFERROR(INDEX([6]HELPER!$E$2:$E$32,MATCH(TRUE,TRIM([6]HELPER!$B$2:$B$32)="MET LUX",0)),IFERROR(INDEX([6]HELPER!$E$2:$E$32,MATCH(TRUE,TRIM([6]HELPER!$C$2:$C$32)="MET LUX",0)),IFERROR(INDEX([6]HELPER!$E$2:$E$32,MATCH(TRUE,TRIM([6]HELPER!$D$2:$D$32)="MET LUX",0)),0)))), _xlpm.helperCost,IFERROR(INDEX([6]HELPER!$E$2:$E$32,MATCH(TRUE,TRIM([6]HELPER!$A$2:$A$32)=_xlpm.mat,0)),IFERROR(INDEX([6]HELPER!$E$2:$E$32,MATCH(TRUE,TRIM([6]HELPER!$B$2:$B$32)=_xlpm.mat,0)),IFERROR(INDEX([6]HELPER!$E$2:$E$32,MATCH(TRUE,TRIM([6]HELPER!$C$2:$C$32)=_xlpm.mat,0)),IFERROR(INDEX([6]HELPER!$E$2:$E$32,MATCH(TRUE,TRIM([6]HELPER!$D$2:$D$32)=_xlpm.mat,0)),"")))), _xlpm.specialCost,IFERROR(_xlfn.XLOOKUP(_xlpm.mat,[6]HELPER!$CK$2:$CK$105,[6]HELPER!$CO$2:$CO$105,""),""), _xlpm.nkHelperCost,IFERROR(INDEX([6]HELPER!$E$2:$E$32,MATCH(TRUE,TRIM([6]HELPER!$A$2:$A$32)="NK",0)),IFERROR(INDEX([6]HELPER!$E$2:$E$32,MATCH(TRUE,TRIM([6]HELPER!$B$2:$B$32)="NK",0)),IFERROR(INDEX([6]HELPER!$E$2:$E$32,MATCH(TRUE,TRIM([6]HELPER!$C$2:$C$32)="NK",0)),IFERROR(INDEX([6]HELPER!$E$2:$E$32,MATCH(TRUE,TRIM([6]HELPER!$D$2:$D$32)="NK",0)),0)))), _xlpm.baseCost,IF(LEFT(_xlpm.mat,4)="TIPA",IF(_xlpm.finalFilmCost<>"",_xlpm.finalFilmCost,_xlpm.specialCost),_xlpm.helperCost), _xlpm.rawResult,IF(OR(_xlpm.mat="NK",_xlpm.mat="NKR",_xlpm.mat="NVS"),_xlpm.nkHelperCost,IF(_xlpm.baseCost="","",IF(OR(_xlpm.finalFilmCost<>"",LEFT(_xlpm.mat,4)="TIPA"),_xlpm.baseCost,_xlpm.baseCost+_xlpm.euShip))), _xlpm.upliftFilm,ISNUMBER(MATCH(_xlpm.matKey,{"TIPA312MET";"TIPA302FG";"TIPA302FGW";"TIPA306M";"TIPA306W";"TIPA312MFG";"TIPA312MFGW"},0)), _xlpm.rawResult ))} -> 8.1897203 | P4: =IF(OR(C4="",A$3<=0),"",IFERROR(IF(O$3="Europe to US",IF(A$3<500,10,IF(A$3<1000,8,IF(A$3<2500,6,IF(A$3<5000,5,4)))),VLOOKUP(O$3,[6]HELPER!$AF$2:$AH$3,3,FALSE)),0)) -> 0 | X4: =IF($K4="","",IFERROR($M4*($N4+$P4),"")) -> 0.18426871 | Z4: =IF($M4="","",IFERROR(($N4+$P4)*$M4/$M$8,"")) -> 2.4939462 | AG4: 📏 Total Thickness | AH4: 80 | AI4: µ | AK4: 📏 Total Thickness | AL4: 80 | AM4: µ | AO4: 📏 Total Thickness | AP4: 80 | AQ4: µ
C5: TIPA 312 MET | J5: =IF(C5="","",$E$3+16) -> 720 | K5: {=_xlfn.LET(_xlpm.baseThick,IFERROR(INDEX([6]HELPER!$BX$2:$BX$250,MATCH(1,(TEXT([6]HELPER!$BZ$2:$BZ$250,"0")=TEXT($B$3,"0"))*([6]HELPER!$CC$2:$CC$250=$AH$4)*([6]HELPER!$BW$2:$BW$250=C5),0)),""),IF(_xlpm.baseThick="","",_xlpm.baseThick))} -> 25 | L5: =IFERROR(VLOOKUP(C5,[6]HELPER!$AP$1:$AQ$25,2,FALSE),"") -> 1.25 | M5: =IF(C5="","",IF(ISNUMBER(SEARCH("paper",C5)),42/1000*(J5/1000),IF(OR(L5="",L5=0),"",L5*1000*(K5/1000000)*(J5/1000)))) -> 0.0225 | N5: {=IF($C5="","",_xlfn.LET( _xlpm.mat,TRIM($C5), _xlpm.matKey,UPPER(SUBSTITUTE(_xlpm.mat," ","")), _xlpm.pr,IFERROR(LOOKUP(2,1/($H$3:H5<>""),$H$3:H5),""), _xlpm.widthActual,IFERROR(LOOKUP(2,1/($E$3:E5<>""),$E$3:E5),$E5), _xlpm.euShip,IFERROR([6]HELPER!$AH$3,0), _xlpm.metSetup,IFERROR([6]HELPER!$CH$2,0), _xlpm.filmNames,[6]!Table1[Film Type], _xlpm.filmCosts,[6]!Table1[For Laminates calculation purposes], _xlpm.printCosts,[6]!Table1[Printing], _xlpm.printWaste,[6]!Table1[Printing Waste], _xlpm.filmCost,IF(LEFT(_xlpm.mat,4)="TIPA",IFERROR(IF(_xlpm.pr="Not Printed",MIN(_xlfn._xlws.FILTER(_xlpm.filmCosts,(UPPER(SUBSTITUTE(_xlpm.filmNames," ",""))=_xlpm.matKey)*(_xlpm.printCosts=0)*(_xlpm.printWaste=0)*(_xlpm.filmCosts>0))),INDEX(_xlfn._xlws.FILTER(_xlpm.filmCosts,(UPPER(SUBSTITUTE(_xlpm.filmNames," ",""))=_xlpm.matKey)*(_xlpm.filmCosts>0)),1)),""),""), _xlpm.summaryNames,"", _xlpm.summaryThick,"", _xlpm.summaryCosts,"", _xlpm.summaryCost,IF(LEFT(_xlpm.mat,4)="TIPA",IFERROR(IF(_xlpm.pr="Not Printed",MIN(_xlfn._xlws.FILTER(_xlpm.summaryCosts,(UPPER(SUBSTITUTE(_xlpm.summaryNames," ",""))=_xlpm.matKey)*(_xlpm.summaryThick=$K5)*(_xlpm.summaryCosts>0))),INDEX(_xlfn._xlws.FILTER(_xlpm.summaryCosts,(UPPER(SUBSTITUTE(_xlpm.summaryNames," ",""))=_xlpm.matKey)*(_xlpm.summaryThick=$K5)*(_xlpm.summaryCosts>0)),1)),""),""), _xlpm.finalFilmCost,IF(_xlpm.filmCost<>"",_xlpm.filmCost,_xlpm.summaryCost), _xlpm.metFilmCost,IFERROR(INDEX(_xlpm.filmCosts,MATCH("TIPA 312 MFG",_xlpm.filmNames,0)),INDEX(_xlpm.filmCosts,1)), _xlpm.tipa312MfgCost,IFERROR(IF(_xlpm.pr="Not Printed",MIN(_xlfn._xlws.FILTER(_xlpm.filmCosts,(UPPER(SUBSTITUTE(_xlpm.filmNames," ",""))="TIPA312MFG")*(_xlpm.printCosts=0)*(_xlpm.printWaste=0)*(_xlpm.filmCosts>0))),INDEX(_xlfn._xlws.FILTER(_xlpm.filmCosts,(UPPER(SUBSTITUTE(_xlpm.filmNames," ",""))="TIPA312MFG")*(_xlpm.filmCosts>0)),1)),0), _xlpm.metluxCost,IFERROR(INDEX([6]HELPER!$E$2:$E$32,MATCH(TRUE,TRIM([6]HELPER!$A$2:$A$32)="MET LUX",0)),IFERROR(INDEX([6]HELPER!$E$2:$E$32,MATCH(TRUE,TRIM([6]HELPER!$B$2:$B$32)="MET LUX",0)),IFERROR(INDEX([6]HELPER!$E$2:$E$32,MATCH(TRUE,TRIM([6]HELPER!$C$2:$C$32)="MET LUX",0)),IFERROR(INDEX([6]HELPER!$E$2:$E$32,MATCH(TRUE,TRIM([6]HELPER!$D$2:$D$32)="MET LUX",0)),0)))), _xlpm.helperCost,IFERROR(INDEX([6]HELPER!$E$2:$E$32,MATCH(TRUE,TRIM([6]HELPER!$A$2:$A$32)=_xlpm.mat,0)),IFERROR(INDEX([6]HELPER!$E$2:$E$32,MATCH(TRUE,TRIM([6]HELPER!$B$2:$B$32)=_xlpm.mat,0)),IFERROR(INDEX([6]HELPER!$E$2:$E$32,MATCH(TRUE,TRIM([6]HELPER!$C$2:$C$32)=_xlpm.mat,0)),IFERROR(INDEX([6]HELPER!$E$2:$E$32,MATCH(TRUE,TRIM([6]HELPER!$D$2:$D$32)=_xlpm.mat,0)),"")))), _xlpm.specialCost,IFERROR(_xlfn.XLOOKUP(_xlpm.mat,[6]HELPER!$CK$2:$CK$105,[6]HELPER!$CO$2:$CO$105,""),""), _xlpm.nkHelperCost,IFERROR(INDEX([6]HELPER!$E$2:$E$32,MATCH(TRUE,TRIM([6]HELPER!$A$2:$A$32)="NK",0)),IFERROR(INDEX([6]HELPER!$E$2:$E$32,MATCH(TRUE,TRIM([6]HELPER!$B$2:$B$32)="NK",0)),IFERROR(INDEX([6]HELPER!$E$2:$E$32,MATCH(TRUE,TRIM([6]HELPER!$C$2:$C$32)="NK",0)),IFERROR(INDEX([6]HELPER!$E$2:$E$32,MATCH(TRUE,TRIM([6]HELPER!$D$2:$D$32)="NK",0)),0)))), _xlpm.baseCost,IF(LEFT(_xlpm.mat,4)="TIPA",IF(_xlpm.finalFilmCost<>"",_xlpm.finalFilmCost,_xlpm.specialCost),_xlpm.helperCost), _xlpm.rawResult,IF(OR(_xlpm.mat="NK",_xlpm.mat="NKR",_xlpm.mat="NVS"),_xlpm.nkHelperCost,IF(_xlpm.baseCost="","",IF(OR(_xlpm.finalFilmCost<>"",LEFT(_xlpm.mat,4)="TIPA"),_xlpm.baseCost,_xlpm.baseCost+_xlpm.euShip))), _xlpm.upliftFilm,ISNUMBER(MATCH(_xlpm.matKey,{"TIPA312MET";"TIPA302FG";"TIPA302FGW";"TIPA306M";"TIPA306W";"TIPA312MFG";"TIPA312MFGW"},0)), _xlpm.rawResult ))} -> 8.1897203 | P5: =IF(OR(C5="",A$3<=0),"",IFERROR(IF(O$3="Europe to US",IF(A$3<500,10,IF(A$3<1000,8,IF(A$3<2500,6,IF(A$3<5000,5,4)))),VLOOKUP(O$3,[6]HELPER!$AF$2:$AH$3,3,FALSE)),0)) -> 0 | X5: =IF($K5="","",IFERROR($M5*($N5+$P5),"")) -> 0.18426871 | Z5: =IF($M5="","",IFERROR(($N5+$P5)*$M5/$M$8,"")) -> 2.4939462 | AG5: 📐 Width of Reel | AH5: 352 | AI5: mm | AK5: 📐 Width of Reel | AL5: 352 | AM5: mm | AO5: 📐 Width of Reel | AP5: 352 | AQ5: mm
C6: RM G Epotal ECO 3675 | J6: =IF(C6="","",$E$3+16) -> 720 | K6: {=_xlfn.LET(_xlpm.baseThick,IFERROR(INDEX([6]HELPER!$BX$2:$BX$250,MATCH(1,(TEXT([6]HELPER!$BZ$2:$BZ$250,"0")=TEXT($B$3,"0"))*([6]HELPER!$CC$2:$CC$250=$AH$4)*([6]HELPER!$BW$2:$BW$250=C6),0)),""),IF(_xlpm.baseThick="","",_xlpm.baseThick))} -> 7 | L6: =IFERROR(VLOOKUP(C6,[6]HELPER!$AP$1:$AQ$25,2,FALSE),"") -> 1 | M6: =IF(C6="","",IF(ISNUMBER(SEARCH("paper",C6)),42/1000*(J6/1000),IF(OR(L6="",L6=0),"",L6*1000*(K6/1000000)*(J6/1000)))) -> 0.00504 | N6: {=IF($C6="","",_xlfn.LET( _xlpm.mat,TRIM($C6), _xlpm.matKey,UPPER(SUBSTITUTE(_xlpm.mat," ","")), _xlpm.pr,IFERROR(LOOKUP(2,1/($H$3:H6<>""),$H$3:H6),""), _xlpm.widthActual,IFERROR(LOOKUP(2,1/($E$3:E6<>""),$E$3:E6),$E6), _xlpm.euShip,IFERROR([6]HELPER!$AH$3,0), _xlpm.metSetup,IFERROR([6]HELPER!$CH$2,0), _xlpm.filmNames,[6]!Table1[Film Type], _xlpm.filmCosts,[6]!Table1[For Laminates calculation purposes], _xlpm.printCosts,[6]!Table1[Printing], _xlpm.printWaste,[6]!Table1[Printing Waste], _xlpm.filmCost,IF(LEFT(_xlpm.mat,4)="TIPA",IFERROR(IF(_xlpm.pr="Not Printed",MIN(_xlfn._xlws.FILTER(_xlpm.filmCosts,(UPPER(SUBSTITUTE(_xlpm.filmNames," ",""))=_xlpm.matKey)*(_xlpm.printCosts=0)*(_xlpm.printWaste=0)*(_xlpm.filmCosts>0))),INDEX(_xlfn._xlws.FILTER(_xlpm.filmCosts,(UPPER(SUBSTITUTE(_xlpm.filmNames," ",""))=_xlpm.matKey)*(_xlpm.filmCosts>0)),1)),""),""), _xlpm.summaryNames,"", _xlpm.summaryThick,"", _xlpm.summaryCosts,"", _xlpm.summaryCost,IF(LEFT(_xlpm.mat,4)="TIPA",IFERROR(IF(_xlpm.pr="Not Printed",MIN(_xlfn._xlws.FILTER(_xlpm.summaryCosts,(UPPER(SUBSTITUTE(_xlpm.summaryNames," ",""))=_xlpm.matKey)*(_xlpm.summaryThick=$K6)*(_xlpm.summaryCosts>0))),INDEX(_xlfn._xlws.FILTER(_xlpm.summaryCosts,(UPPER(SUBSTITUTE(_xlpm.summaryNames," ",""))=_xlpm.matKey)*(_xlpm.summaryThick=$K6)*(_xlpm.summaryCosts>0)),1)),""),""), _xlpm.finalFilmCost,IF(_xlpm.filmCost<>"",_xlpm.filmCost,_xlpm.summaryCost), _xlpm.metFilmCost,IFERROR(INDEX(_xlpm.filmCosts,MATCH("TIPA 312 MFG",_xlpm.filmNames,0)),INDEX(_xlpm.filmCosts,1)), _xlpm.tipa312MfgCost,IFERROR(IF(_xlpm.pr="Not Printed",MIN(_xlfn._xlws.FILTER(_xlpm.filmCosts,(UPPER(SUBSTITUTE(_xlpm.filmNames," ",""))="TIPA312MFG")*(_xlpm.printCosts=0)*(_xlpm.printWaste=0)*(_xlpm.filmCosts>0))),INDEX(_xlfn._xlws.FILTER(_xlpm.filmCosts,(UPPER(SUBSTITUTE(_xlpm.filmNames," ",""))="TIPA312MFG")*(_xlpm.filmCosts>0)),1)),0), _xlpm.metluxCost,IFERROR(INDEX([6]HELPER!$E$2:$E$32,MATCH(TRUE,TRIM([6]HELPER!$A$2:$A$32)="MET LUX",0)),IFERROR(INDEX([6]HELPER!$E$2:$E$32,MATCH(TRUE,TRIM([6]HELPER!$B$2:$B$32)="MET LUX",0)),IFERROR(INDEX([6]HELPER!$E$2:$E$32,MATCH(TRUE,TRIM([6]HELPER!$C$2:$C$32)="MET LUX",0)),IFERROR(INDEX([6]HELPER!$E$2:$E$32,MATCH(TRUE,TRIM([6]HELPER!$D$2:$D$32)="MET LUX",0)),0)))), _xlpm.helperCost,IFERROR(INDEX([6]HELPER!$E$2:$E$32,MATCH(TRUE,TRIM([6]HELPER!$A$2:$A$32)=_xlpm.mat,0)),IFERROR(INDEX([6]HELPER!$E$2:$E$32,MATCH(TRUE,TRIM([6]HELPER!$B$2:$B$32)=_xlpm.mat,0)),IFERROR(INDEX([6]HELPER!$E$2:$E$32,MATCH(TRUE,TRIM([6]HELPER!$C$2:$C$32)=_xlpm.mat,0)),IFERROR(INDEX([6]HELPER!$E$2:$E$32,MATCH(TRUE,TRIM([6]HELPER!$D$2:$D$32)=_xlpm.mat,0)),"")))), _xlpm.specialCost,IFERROR(_xlfn.XLOOKUP(_xlpm.mat,[6]HELPER!$CK$2:$CK$105,[6]HELPER!$CO$2:$CO$105,""),""), _xlpm.nkHelperCost,IFERROR(INDEX([6]HELPER!$E$2:$E$32,MATCH(TRUE,TRIM([6]HELPER!$A$2:$A$32)="NK",0)),IFERROR(INDEX([6]HELPER!$E$2:$E$32,MATCH(TRUE,TRIM([6]HELPER!$B$2:$B$32)="NK",0)),IFERROR(INDEX([6]HELPER!$E$2:$E$32,MATCH(TRUE,TRIM([6]HELPER!$C$2:$C$32)="NK",0)),IFERROR(INDEX([6]HELPER!$E$2:$E$32,MATCH(TRUE,TRIM([6]HELPER!$D$2:$D$32)="NK",0)),0)))), _xlpm.baseCost,IF(LEFT(_xlpm.mat,4)="TIPA",IF(_xlpm.finalFilmCost<>"",_xlpm.finalFilmCost,_xlpm.specialCost),_xlpm.helperCost), _xlpm.rawResult,IF(OR(_xlpm.mat="NK",_xlpm.mat="NKR",_xlpm.mat="NVS"),_xlpm.nkHelperCost,IF(_xlpm.baseCost="","",IF(OR(_xlpm.finalFilmCost<>"",LEFT(_xlpm.mat,4)="TIPA"),_xlpm.baseCost,_xlpm.baseCost+_xlpm.euShip))), _xlpm.upliftFilm,ISNUMBER(MATCH(_xlpm.matKey,{"TIPA312MET";"TIPA302FG";"TIPA302FGW";"TIPA306M";"TIPA306W";"TIPA312MFG";"TIPA312MFGW"},0)), _xlpm.rawResult ))} -> 4.85 | P6: =IF(OR(C6="",A$3<=0),"",IFERROR(IF(O$3="Europe to US",IF(A$3<500,10,IF(A$3<1000,8,IF(A$3<2500,6,IF(A$3<5000,5,4)))),VLOOKUP(O$3,[6]HELPER!$AF$2:$AH$3,3,FALSE)),0)) -> 0 | X6: =IF($K6="","",IFERROR($M6*($N6+$P6),"")) -> 0.024444 | Z6: =IF($M6="","",IFERROR(($N6+$P6)*$M6/$M$8,"")) -> 0.3308322 | AG6: ⚖️ Amount (Kg) | AI6: Kg | AK6: ⚖️ Amount (Kg) | AM6: Kg | AO6: ⚖️ Amount (Kg) | AQ6: Kg
J7: =IF(C7="","",$E$3+16) | K7: {=_xlfn.LET(_xlpm.baseThick,IFERROR(INDEX([6]HELPER!$BX$2:$BX$250,MATCH(1,(TEXT([6]HELPER!$BZ$2:$BZ$250,"0")=TEXT($B$3,"0"))*([6]HELPER!$CC$2:$CC$250=$AH$4)*([6]HELPER!$BW$2:$BW$250=C7),0)),""),IF(_xlpm.baseThick="","",_xlpm.baseThick))} | L7: =IFERROR(VLOOKUP(C7,[6]HELPER!$AP$1:$AQ$25,2,FALSE),"") | M7: =IF(C7="","",IF(ISNUMBER(SEARCH("paper",C7)),42/1000*(J7/1000),IF(OR(L7="",L7=0),"",L7*1000*(K7/1000000)*(J7/1000)))) | N7: {=IF($C7="","",_xlfn.LET( _xlpm.mat,TRIM($C7), _xlpm.matKey,UPPER(SUBSTITUTE(_xlpm.mat," ","")), _xlpm.pr,IFERROR(LOOKUP(2,1/($H$3:H7<>""),$H$3:H7),""), _xlpm.widthActual,IFERROR(LOOKUP(2,1/($E$3:E7<>""),$E$3:E7),$E7), _xlpm.euShip,IFERROR([6]HELPER!$AH$3,0), _xlpm.metSetup,IFERROR([6]HELPER!$CH$2,0), _xlpm.filmNames,[6]!Table1[Film Type], _xlpm.filmCosts,[6]!Table1[For Laminates calculation purposes], _xlpm.printCosts,[6]!Table1[Printing], _xlpm.printWaste,[6]!Table1[Printing Waste], _xlpm.filmCost,IF(LEFT(_xlpm.mat,4)="TIPA",IFERROR(IF(_xlpm.pr="Not Printed",MIN(_xlfn._xlws.FILTER(_xlpm.filmCosts,(UPPER(SUBSTITUTE(_xlpm.filmNames," ",""))=_xlpm.matKey)*(_xlpm.printCosts=0)*(_xlpm.printWaste=0)*(_xlpm.filmCosts>0))),INDEX(_xlfn._xlws.FILTER(_xlpm.filmCosts,(UPPER(SUBSTITUTE(_xlpm.filmNames," ",""))=_xlpm.matKey)*(_xlpm.filmCosts>0)),1)),""),""), _xlpm.summaryNames,"", _xlpm.summaryThick,"", _xlpm.summaryCosts,"", _xlpm.summaryCost,IF(LEFT(_xlpm.mat,4)="TIPA",IFERROR(IF(_xlpm.pr="Not Printed",MIN(_xlfn._xlws.FILTER(_xlpm.summaryCosts,(UPPER(SUBSTITUTE(_xlpm.summaryNames," ",""))=_xlpm.matKey)*(_xlpm.summaryThick=$K7)*(_xlpm.summaryCosts>0))),INDEX(_xlfn._xlws.FILTER(_xlpm.summaryCosts,(UPPER(SUBSTITUTE(_xlpm.summaryNames," ",""))=_xlpm.matKey)*(_xlpm.summaryThick=$K7)*(_xlpm.summaryCosts>0)),1)),""),""), _xlpm.finalFilmCost,IF(_xlpm.filmCost<>"",_xlpm.filmCost,_xlpm.summaryCost), _xlpm.metFilmCost,IFERROR(INDEX(_xlpm.filmCosts,MATCH("TIPA 312 MFG",_xlpm.filmNames,0)),INDEX(_xlpm.filmCosts,1)), _xlpm.tipa312MfgCost,IFERROR(IF(_xlpm.pr="Not Printed",MIN(_xlfn._xlws.FILTER(_xlpm.filmCosts,(UPPER(SUBSTITUTE(_xlpm.filmNames," ",""))="TIPA312MFG")*(_xlpm.printCosts=0)*(_xlpm.printWaste=0)*(_xlpm.filmCosts>0))),INDEX(_xlfn._xlws.FILTER(_xlpm.filmCosts,(UPPER(SUBSTITUTE(_xlpm.filmNames," ",""))="TIPA312MFG")*(_xlpm.filmCosts>0)),1)),0), _xlpm.metluxCost,IFERROR(INDEX([6]HELPER!$E$2:$E$32,MATCH(TRUE,TRIM([6]HELPER!$A$2:$A$32)="MET LUX",0)),IFERROR(INDEX([6]HELPER!$E$2:$E$32,MATCH(TRUE,TRIM([6]HELPER!$B$2:$B$32)="MET LUX",0)),IFERROR(INDEX([6]HELPER!$E$2:$E$32,MATCH(TRUE,TRIM([6]HELPER!$C$2:$C$32)="MET LUX",0)),IFERROR(INDEX([6]HELPER!$E$2:$E$32,MATCH(TRUE,TRIM([6]HELPER!$D$2:$D$32)="MET LUX",0)),0)))), _xlpm.helperCost,IFERROR(INDEX([6]HELPER!$E$2:$E$32,MATCH(TRUE,TRIM([6]HELPER!$A$2:$A$32)=_xlpm.mat,0)),IFERROR(INDEX([6]HELPER!$E$2:$E$32,MATCH(TRUE,TRIM([6]HELPER!$B$2:$B$32)=_xlpm.mat,0)),IFERROR(INDEX([6]HELPER!$E$2:$E$32,MATCH(TRUE,TRIM([6]HELPER!$C$2:$C$32)=_xlpm.mat,0)),IFERROR(INDEX([6]HELPER!$E$2:$E$32,MATCH(TRUE,TRIM([6]HELPER!$D$2:$D$32)=_xlpm.mat,0)),"")))), _xlpm.specialCost,IFERROR(_xlfn.XLOOKUP(_xlpm.mat,[6]HELPER!$CK$2:$CK$105,[6]HELPER!$CO$2:$CO$105,""),""), _xlpm.nkHelperCost,IFERROR(INDEX([6]HELPER!$E$2:$E$32,MATCH(TRUE,TRIM([6]HELPER!$A$2:$A$32)="NK",0)),IFERROR(INDEX([6]HELPER!$E$2:$E$32,MATCH(TRUE,TRIM([6]HELPER!$B$2:$B$32)="NK",0)),IFERROR(INDEX([6]HELPER!$E$2:$E$32,MATCH(TRUE,TRIM([6]HELPER!$C$2:$C$32)="NK",0)),IFERROR(INDEX([6]HELPER!$E$2:$E$32,MATCH(TRUE,TRIM([6]HELPER!$D$2:$D$32)="NK",0)),0)))), _xlpm.baseCost,IF(LEFT(_xlpm.mat,4)="TIPA",IF(_xlpm.finalFilmCost<>"",_xlpm.finalFilmCost,_xlpm.specialCost),_xlpm.helperCost), _xlpm.rawResult,IF(OR(_xlpm.mat="NK",_xlpm.mat="NKR",_xlpm.mat="NVS"),_xlpm.nkHelperCost,IF(_xlpm.baseCost="","",IF(OR(_xlpm.finalFilmCost<>"",LEFT(_xlpm.mat,4)="TIPA"),_xlpm.baseCost,_xlpm.baseCost+_xlpm.euShip))), _xlpm.upliftFilm,ISNUMBER(MATCH(_xlpm.matKey,{"TIPA312MET";"TIPA302FG";"TIPA302FGW";"TIPA306M";"TIPA306W";"TIPA312MFG";"TIPA312MFGW"},0)), _xlpm.rawResult ))} | P7: =IF(OR(C7="",A$3<=0),"",IFERROR(IF(O$3="Europe to US",IF(A$3<500,10,IF(A$3<1000,8,IF(A$3<2500,6,IF(A$3<5000,5,4)))),VLOOKUP(O$3,[6]HELPER!$AF$2:$AH$3,3,FALSE)),0)) | X7: =IF($K7="","",IFERROR($M7*($N7+$P7),"")) | Z7: =IF($M7="","",IFERROR(($N7+$P7)*$M7/$M$8,"")) | AG7: 🖨️ PR/NonPR | AH7: Printed | AK7: 🖨️ PR/NonPR | AL7: Printed | AO7: 🖨️ PR/NonPR | AP7: Printed
